<?xml version="1.0" ?>
<!-- =================================================================================== -->
<!-- |    This document was autogenerated by xacro from bam_v1_left.urdf.xacro         | -->
<!-- |    EDITING THIS FILE BY HAND IS NOT RECOMMENDED                                 | -->
<!-- =================================================================================== -->
<robot name="bam_v1_left">
  <material name="StoglRobotics/Violet">
    <color rgba="0.4 0.1803921568627451 0.5686274509803921 1.0"/>
    <ambient>1 0 0 1</ambient>
    <diffuse>1 0 0 1</diffuse>
    <specular>0.1 0.1 0.1 1</specular>
    <emissive>0 0 0 0</emissive>
  </material>
  <material name="StoglRobotics/DarkGrey">
    <color rgba="0.2 0.2 0.2 1.0"/>
    <ambient>1 0 0 1</ambient>
    <diffuse>1 0 0 1</diffuse>
    <specular>0.1 0.1 0.1 1</specular>
    <emissive>0 0 0 0</emissive>
  </material>
  <material name="StoglRobotics/LightGrey">
    <color rgba="0.7607843137254902 0.7607843137254902 0.7607843137254902 1.0"/>
    <ambient>1 0 0 1</ambient>
    <diffuse>1 0 0 1</diffuse>
    <specular>0.1 0.1 0.1 1</specular>
    <emissive>0 0 0 0</emissive>
  </material>
  <material name="Ghost">
    <color rgba="0.7607843137254902 0.7607843137254902 0.7607843137254902 0.5"/>
    <ambient>1 0 0 1</ambient>
    <diffuse>1 0 0 1</diffuse>
    <specular>0.1 0.1 0.1 1</specular>
    <emissive>0 0 0 0</emissive>
  </material>
  <material name="Black">
    <color rgba="0.0 0.0 0.0 1"/>
    <ambient>1 0 0 1</ambient>
    <diffuse>1 0 0 1</diffuse>
    <specular>0.1 0.1 0.1 1</specular>
    <emissive>0 0 0 0</emissive>
  </material>
  <material name="White">
    <color rgba="1.0 1.0 1.0 1"/>
    <ambient>1 0 0 1</ambient>
    <diffuse>1 0 0 1</diffuse>
    <specular>0.1 0.1 0.1 1</specular>
    <emissive>0 0 0 0</emissive>
  </material>
  <!-- FOR TESTING UNCOMMENT  -->
  <!-- <xacro:bam_v1_urdf side="right" reflect="1"/> -->
  <!-- <xacro:include filename="$(find bam_descriptions)/urdf/common.xacro" /> -->
  <!-- if include this here, there may be errors if included agian -->
  <!-- FOR TESTING UNCOMMENT  -->
  <!-- <xacro:bam_v1 side="right" reflect="1"/>
    <link name="base_link"/>
    <joint name="base_link_joint" type="fixed">
        <origin xyz="0 0 0" rpy="0.0 0.0 0.0"/>
        <parent link="base_link"/>
        <child link="right_base_link"/>
    </joint> -->
  <link name="left_base_link">
    <visual>
      <geometry>
        <mesh filename="package://bam_descriptions/meshes/side_base_link.stl"/>
      </geometry>
      <origin xyz="0.0 0.0 0.0"/>
      <material name="StoglRobotics/LightGrey"/>
    </visual>
    <collision>
      <geometry>
        <mesh filename="package://bam_descriptions/meshes/side_base_link.stl"/>
      </geometry>
      <origin xyz="0.0 0.0 0.0"/>
    </collision>
  </link>
  <joint name="left_joint_1" type="revolute">
    <origin rpy="0 0 0" xyz="0 0 -0.026"/>
    <parent link="left_base_link"/>
    <child link="left_gimbal_link"/>
    <axis xyz="0 0 1"/>
    <limit effort="5.0" lower="-2.356194490192345" upper="1.5707963267948966" velocity="10.0"/>
  </joint>
  <link name="left_gimbal_link">
    <visual>
      <geometry>
        <mesh filename="package://bam_descriptions/meshes/gimbal_link.stl"/>
      </geometry>
      <material name="StoglRobotics/LightGrey"/>
    </visual>
    <collision>
      <geometry>
        <mesh filename="package://bam_descriptions/meshes/gimbal_link.stl"/>
      </geometry>
    </collision>
  </link>
  <joint name="left_joint_2" type="revolute">
    <origin rpy="-1.5707963267948966 0 0" xyz="0 0.0465 -0.0685"/>
    <parent link="left_gimbal_link"/>
    <child link="left_shoulder_link"/>
    <axis xyz="0.0 0.0 1"/>
    <limit effort="5.0" lower="-0.7853981633974483" upper="3.141592653589793" velocity="10.0"/>
  </joint>
  <link name="left_shoulder_link">
    <visual>
      <geometry>
        <mesh filename="package://bam_descriptions/meshes/shoulder_link.stl"/>
      </geometry>
      <origin rpy="0 0 1.5707963267948966" xyz="0 0 0"/>
      <material name="StoglRobotics/LightGrey"/>
    </visual>
    <collision>
      <geometry>
        <mesh filename="package://bam_descriptions/meshes/shoulder_link.stl"/>
      </geometry>
      <origin rpy="0 0 1.5707963267948966" xyz="0 0 0"/>
    </collision>
  </link>
  <joint name="left_joint_3" type="revolute">
    <origin rpy="0.0 1.5707963267948966 0" xyz="0.0 0.0 -0.0465"/>
    <parent link="left_shoulder_link"/>
    <child link="left_upper_arm_link"/>
    <axis xyz="0 0 1"/>
    <limit effort="5.0" lower="-1.5707963267948966" upper="1.5707963267948966" velocity="10.0"/>
    <!-- <limit lower="${-pi}" upper="${pi}" effort="5.0" velocity="10.0"/> -->
  </joint>
  <link name="left_upper_arm_link">
    <visual>
      <geometry>
        <mesh filename="package://bam_descriptions/meshes/six_dof/upper_arm_left.stl"/>
      </geometry>
      <origin rpy="0 0 1.5707963267948966" xyz="0 0 0"/>
      <material name="StoglRobotics/LightGrey"/>
    </visual>
    <collision>
      <geometry>
        <mesh filename="package://bam_descriptions/meshes/six_dof/upper_arm_left.stl"/>
      </geometry>
      <origin rpy="0 0 1.5707963267948966" xyz="0 0 0"/>
    </collision>
  </link>
  <joint name="left_joint_4" type="revolute">
    <origin rpy="0.0 0.0 0.0" xyz="0.0 0.27 0.0635"/>
    <parent link="left_upper_arm_link"/>
    <child link="left_elbow_link"/>
    <axis xyz="0 0 1"/>
    <limit effort="5.0" lower="0" upper="2.6179938779914944" velocity="10.0"/>
  </joint>
  <link name="left_elbow_link">
    <visual>
      <geometry>
        <mesh filename="package://bam_descriptions/meshes/six_dof/elbow_link.stl"/>
      </geometry>
      <origin rpy="0 0 1.5707963267948966" xyz="0 0 0"/>
      <material name="StoglRobotics/LightGrey"/>
    </visual>
    <collision>
      <geometry>
        <mesh filename="package://bam_descriptions/meshes/six_dof/elbow_link.stl"/>
      </geometry>
      <origin rpy="0 0 1.5707963267948966" xyz="0 0 0"/>
    </collision>
  </link>
  <joint name="left_joint_5" type="revolute">
    <origin rpy="1.5707963267948966 0.0 0.0" xyz="0.042 0.006 0"/>
    <parent link="left_elbow_link"/>
    <child link="left_lower_arm_link"/>
    <axis xyz="0 0 1"/>
    <limit effort="5.0" lower="-3.015928947446201" upper="3.015928947446201" velocity="10.0"/>
  </joint>
  <link name="left_lower_arm_link">
    <visual>
      <geometry>
        <mesh filename="package://bam_descriptions/meshes/six_dof/lower_arm.stl"/>
      </geometry>
      <origin rpy="0 0 -1.5707963267948966" xyz="0 0 0"/>
      <material name="StoglRobotics/LightGrey"/>
    </visual>
    <collision>
      <geometry>
        <mesh filename="package://bam_descriptions/meshes/six_dof/lower_arm.stl"/>
      </geometry>
      <origin rpy="0 0 -1.5707963267948966" xyz="0 0 0"/>
    </collision>
  </link>
  <joint name="left_joint_6" type="revolute">
    <origin rpy="-1.5707963267948966 0.0 0.0" xyz="0.0 0.0 -0.285"/>
    <parent link="left_lower_arm_link"/>
    <child link="left_hand_link"/>
    <axis xyz="0 0 1"/>
    <limit effort="5.0" lower="-3.141592653589793" upper="0" velocity="10.0"/>
  </joint>
  <link name="left_hand_link">
    <visual>
      <geometry>
        <mesh filename="package://bam_descriptions/meshes/six_dof/hand_link.stl"/>
      </geometry>
      <origin rpy="-1.5707963267948966 3.141592653589793 0" xyz="0 0 0"/>
      <material name="StoglRobotics/LightGrey"/>
    </visual>
    <collision>
      <geometry>
        <mesh filename="package://bam_descriptions/meshes/six_dof/hand_link.stl"/>
      </geometry>
      <!-- <origin xyz="0 0 0" rpy="0 0 ${-pi/2}" /> -->
    </collision>
  </link>
  <joint name="left_joint_7" type="revolute">
    <origin rpy="0.0 0.0 0.0" xyz="0.0135 0.078425 0"/>
    <parent link="left_hand_link"/>
    <child link="left_finger_1"/>
    <axis xyz="0 0 1"/>
    <limit effort="5.0" lower="0" upper="0.26" velocity="10.0"/>
  </joint>
  <link name="left_finger_1">
    <visual>
      <geometry>
        <cylinder length="0.075" radius="0.007"/>
      </geometry>
      <origin rpy="1.5707963267948966 0 0" xyz="0 0.0375 0"/>
      <material name="StoglRobotics/LightGrey"/>
    </visual>
    <collision>
      <geometry>
        <cylinder length="0" radius="0"/>
      </geometry>
      <origin rpy="0 0 0" xyz="0 0 0"/>
    </collision>
  </link>
  <joint name="left_joint_8" type="revolute">
    <origin rpy="0.0 0.0 0.0" xyz="-0.0335 0.078425 0"/>
    <parent link="left_hand_link"/>
    <child link="left_finger_2"/>
    <axis xyz="0 0 1"/>
    <limit effort="5.0" lower="-0.26" upper="0" velocity="10.0"/>
    <mimic joint="left_joint_7" multiplier="-1.0"/>
  </joint>
  <link name="left_finger_2">
    <visual>
      <geometry>
        <cylinder length="0.075" radius="0.007"/>
      </geometry>
      <origin rpy="1.5707963267948966 0 0" xyz="0 0.0375 0"/>
      <material name="StoglRobotics/LightGrey"/>
    </visual>
    <collision>
      <geometry>
        <cylinder length="0" radius="0"/>
      </geometry>
      <origin rpy="0 0 0" xyz="0 0 0"/>
    </collision>
  </link>
  <joint name="left_finger_tip_transform" type="fixed">
    <origin rpy="1.5707963267948966 -1.5707963267948966 0" xyz="-0.01 0.15342499999999998 0"/>
    <parent link="left_hand_link"/>
    <child link="left_finger_tip"/>
  </joint>
  <link name="left_finger_tip"/>
  <joint name="left_eef_transform" type="fixed">
    <origin rpy="1.5707963267948966 -1.5707963267948966 0" xyz="-0.01 0.15342499999999998 0"/>
    <parent link="left_hand_link"/>
    <child link="left_eef_target"/>
  </joint>
  <link name="left_eef_target"/>

  <!-- Define New Base Link in Center -->
  <link name="base_link"/>
  <joint name="rack_fixed_joint" type="fixed">
    <origin rpy="0.0 0.0 0" xyz="0.0 0.0 0.0"/>
    <parent link="base_link"/>
    <child link="rack"/>
  </joint>
  <link name="rack">
    <visual>
      <origin rpy="0 0 0" xyz="0 0 0"/>
      <geometry>
        <mesh filename="package://bam_descriptions/meshes/rack.stl"/>
      </geometry>
      <material name="StoglRobotics/LightGrey"/>
    </visual>
  </link>
  <joint name="left_fixed_joint" type="fixed">
    <origin rpy="0.0 0.0 0" xyz="-0.14 0.0 0.0"/>
    <parent link="rack"/>
    <child link="left_base_link"/>
  </joint>

</robot>
